<?xml version="1.0"?>
<robot name="UR3__99__">
    <link name="UR3__99__">
        <inertial>
            <origin xyz="0.000079 0.000098 -0.005218" rpy="-3.140614 3.141544 -1.823162" />
            <inertia iyz="0.0" iyy="0.0014176038093865" ixz="0.0" ixy="0.0" izz="0.0016785468906164" ixx="0.0014156427932903" />
            <mass value="1.0" />
        </inertial>
        <collision>
            <origin xyz="0.000000 0.000000 0.000000" rpy="-3.141593 3.141593 -3.141593" />
            <geometry>
                <mesh filename="file://E:/Desktop/SpaRoboModel/SPART_based_modelling/MyURDF/UR3_UR3__99__.dae" />
            </geometry>
        </collision>
        <visual>
            <origin xyz="0.000125 0.000086 -0.000000" rpy="-3.141593 3.141593 -3.141593" />
            <geometry>
                <mesh filename="file://E:/Desktop/SpaRoboModel/SPART_based_modelling/MyURDF/UR3_link1_visible__100__.dae" />
            </geometry>
            <material name="link1_visible__100___material">
                <color rgba="0.282353 0.282353 0.282353 1.0" />
            </material>
        </visual>
    </link>
    <link name="link__102__">
        <inertial>
            <origin xyz="-0.003125 0.000075 -0.001374" rpy="3.042686 3.141884 -1.570929" />
            <inertia iyz="0.0" iyy="0.013356528244913" ixz="0.0" ixy="0.0" izz="0.0099014118313789" ixx="0.014095027931035" />
            <mass value="1.0" />
        </inertial>
        <collision>
            <origin xyz="0.000000 0.000000 0.000000" rpy="-3.141593 3.141593 -3.141593" />
            <geometry>
                <mesh filename="file://E:/Desktop/SpaRoboModel/SPART_based_modelling/MyURDF/UR3_link__102__.dae" />
            </geometry>
        </collision>
        <visual>
            <origin xyz="0.000000 -0.000000 0.000354" rpy="-3.141593 3.141593 -3.141593" />
            <geometry>
                <mesh filename="file://E:/Desktop/SpaRoboModel/SPART_based_modelling/MyURDF/UR3_link2_visible__103__.dae" />
            </geometry>
            <material name="link2_visible__103___material">
                <color rgba="0.282353 0.282353 0.282353 1.0" />
            </material>
        </visual>
    </link>
    <joint type="revolute" name="joint__101__">
        <axis xyz="0 0 1" />
        <limit effort="50.0" velocity="3.1415927410126" upper="6.2831854820251" lower="-6.2831854820251" />
        <parent link="UR3__99__" />
        <child link="link__102__" />
        <origin xyz="-0.003618 -0.000070 0.104020" rpy="-3.141593 3.141593 -3.141593" />
    </joint>
    <link name="link__105__">
        <inertial>
            <origin xyz="-0.002925 -0.000115 -0.017841" rpy="3.088942 3.142220 -1.574821" />
            <inertia iyz="0.0" iyy="0.21194118261337" ixz="0.0" ixy="0.0" izz="0.024627504870296" ixx="0.21848785877228" />
            <mass value="2.5" />
        </inertial>
        <collision>
            <origin xyz="0.000000 0.000000 0.000000" rpy="-3.141593 3.141593 -3.141593" />
            <geometry>
                <mesh filename="file://E:/Desktop/SpaRoboModel/SPART_based_modelling/MyURDF/UR3_link__105__.dae" />
            </geometry>
        </collision>
        <visual>
            <origin xyz="0.000073 0.000000 0.000146" rpy="-3.141593 3.141593 -3.141593" />
            <geometry>
                <mesh filename="file://E:/Desktop/SpaRoboModel/SPART_based_modelling/MyURDF/UR3_link3_visible__106__.dae" />
            </geometry>
            <material name="link3_visible__106___material">
                <color rgba="0.508235 0.761224 0.903529 1.0" />
            </material>
        </visual>
    </link>
    <joint type="revolute" name="joint__104__">
        <axis xyz="0 0 1" />
        <limit effort="50.0" velocity="3.1415927410126" upper="6.2831854820251" lower="-6.2831854820251" />
        <parent link="link__102__" />
        <child link="link__105__" />
        <origin xyz="-0.111774 0.000281 0.122645" rpy="-3.141593 3.141593 -3.141593" />
    </joint>
    <link name="link__108__">
        <inertial>
            <origin xyz="-0.003855 0.000135 0.014216" rpy="-3.087552 3.142110 -1.560338" />
            <inertia iyz="0.0" iyy="0.14924985170364" ixz="0.0" ixy="0.0" izz="0.01328753773123" ixx="0.15226745605469" />
            <mass value="2.5" />
        </inertial>
        <collision>
            <origin xyz="0.000000 0.000000 0.000000" rpy="-3.141593 3.141593 -3.141593" />
            <geometry>
                <mesh filename="file://E:/Desktop/SpaRoboModel/SPART_based_modelling/MyURDF/UR3_link__108__.dae" />
            </geometry>
        </collision>
        <visual>
            <origin xyz="-0.001048 0.000136 -0.000135" rpy="-3.141593 3.141593 -3.141593" />
            <geometry>
                <mesh filename="file://E:/Desktop/SpaRoboModel/SPART_based_modelling/MyURDF/UR3_link4_visible__109__.dae" />
            </geometry>
            <material name="link4_visible__109___material">
                <color rgba="0.282353 0.282353 0.282353 1.0" />
            </material>
        </visual>
    </link>
    <joint type="revolute" name="joint__107__">
        <axis xyz="0 0 1" />
        <limit effort="50.0" velocity="3.1415927410126" upper="6.2831854820251" lower="-6.2831854820251" />
        <parent link="link__105__" />
        <child link="link__108__" />
        <origin xyz="0.087333 -0.000243 0.229823" rpy="-3.141593 3.141593 -3.141593" />
    </joint>
    <link name="link__111__">
        <inertial>
            <origin xyz="0.001975 -0.000118 0.001445" rpy="3.125834 3.147963 -1.564550" />
            <inertia iyz="0.0" iyy="0.0074614337645471" ixz="0.0" ixy="0.0" izz="0.0046329372562468" ixx="0.0076239206828177" />
            <mass value="1.0" />
        </inertial>
        <collision>
            <origin xyz="0.000000 0.000000 0.000000" rpy="-3.141593 3.141593 -3.141593" />
            <geometry>
                <mesh filename="file://E:/Desktop/SpaRoboModel/SPART_based_modelling/MyURDF/UR3_link__111__.dae" />
            </geometry>
        </collision>
        <visual>
            <origin xyz="0.000961 0.000001 -0.000196" rpy="-3.141593 3.141593 -3.141593" />
            <geometry>
                <mesh filename="file://E:/Desktop/SpaRoboModel/SPART_based_modelling/MyURDF/UR3_link5_visible__112__.dae" />
            </geometry>
            <material name="link5_visible__112___material">
                <color rgba="0.282353 0.282353 0.282353 1.0" />
            </material>
        </visual>
    </link>
    <joint type="revolute" name="joint__110__">
        <axis xyz="0 0 1" />
        <limit effort="50.0" velocity="6.2831854820251" upper="6.2831854820251" lower="-6.2831854820251" />
        <parent link="link__108__" />
        <child link="link__111__" />
        <origin xyz="-0.082905 0.000172 0.110516" rpy="-3.141593 3.141593 -3.141593" />
    </joint>
    <link name="link__114__">
        <inertial>
            <origin xyz="-0.001462 0.000101 -0.001811" rpy="-3.116261 3.128697 -1.573779" />
            <inertia iyz="0.0" iyy="0.0046688904985785" ixz="0.0" ixy="0.0" izz="0.0076049752533436" ixx="0.007785230409354" />
            <mass value="1.0" />
        </inertial>
        <collision>
            <origin xyz="0.000000 0.000000 0.000000" rpy="-3.141593 3.141593 -3.141593" />
            <geometry>
                <mesh filename="file://E:/Desktop/SpaRoboModel/SPART_based_modelling/MyURDF/UR3_link__114__.dae" />
            </geometry>
        </collision>
        <visual>
            <origin xyz="0.000087 -0.000065 -0.000932" rpy="-3.141593 3.141593 -3.141593" />
            <geometry>
                <mesh filename="file://E:/Desktop/SpaRoboModel/SPART_based_modelling/MyURDF/UR3_link6_visible__115__.dae" />
            </geometry>
            <material name="link6_visible__115___material">
                <color rgba="0.282353 0.282353 0.282353 1.0" />
            </material>
        </visual>
    </link>
    <joint type="revolute" name="joint__113__">
        <axis xyz="0 0 1" />
        <limit effort="50.0" velocity="6.2831854820251" upper="6.2831854820251" lower="-6.2831854820251" />
        <parent link="link__111__" />
        <child link="link__114__" />
        <origin xyz="-0.003154 0.000364 0.082919" rpy="-3.141593 3.141593 -3.141593" />
    </joint>
    <link name="link__117__">
        <inertial>
            <origin xyz="-0.000000 -0.000000 -0.000000" rpy="-3.141593 3.141593 -3.141593" />
            <inertia iyz="0.0" iyy="0.0026207731571048" ixz="0.0" ixy="0.0" izz="0.0038703854661435" ixx="0.0026207731571048" />
            <mass value="1.0" />
        </inertial>
        <collision>
            <origin xyz="0.000000 0.000000 0.000000" rpy="-3.141593 3.141593 -3.141593" />
            <geometry>
                <cylinder length="0.032068222761154" radius="0.03120630979538" />
            </geometry>
        </collision>
        <visual>
            <origin xyz="-0.000000 0.003408 0.000000" rpy="-1.570796 -1.570796 0.000000" />
            <geometry>
                <mesh filename="file://E:/Desktop/SpaRoboModel/SPART_based_modelling/MyURDF/UR3_link7_visible__119__.dae" />
            </geometry>
            <material name="link7_visible__119___material">
                <color rgba="0.870588 0.870588 0.870588 1.0" />
            </material>
        </visual>
    </link>
    <joint type="continuous" name="joint__116__">
        <axis xyz="0 0 1" />
        <parent link="link__114__" />
        <child link="link__117__" />
        <origin xyz="-0.063777 -0.000324 0.001394" rpy="-1.570796 3.141593 -1.570796" />
    </joint>
</robot>
